<robot name='cobot_v2_0_Tandem'>

<!-- Links -->

<link name = 'base_link'>

</link>


<link name = 'lin_axis'>
<visual>
<origin rpy = '-1.570796327 3.141592654 0.0' xyz = '0.0 -.35 -0.32' />
<geometry>
<mesh filename='package://cobot_bmw/meshes/lin_axis/axis.stl' scale = '0.001 0.001 0.001' />
<material name='silver'> 
<color rgba = '0.00 0.566 0.859 1.000000' />
</material>
</geometry>
</visual>

<collision>
<origin rpy = '-1.570796327 3.141592654 0' xyz = '0.0 -.35 -0.32' />
<geometry> 
<mesh filename='package://cobot_bmw/meshes/lin_axis/axis.stl' scale = '0.001 0.001 0.001' />
</geometry>
</collision>

</link>

<link name = 'lin_axis_carriage'>
<visual>
<origin rpy = '-1.570796327 3.141592654 0' xyz = '0.0 0.0 -0.32' />
<geometry>
<mesh filename='package://cobot_bmw/meshes/lin_axis/carriage.stl' scale = '0.001 0.001 0.001' />
<material name='silver'> 
<color rgba = '0.00 0.566 0.859 1.000000' />
</material>
</geometry>
</visual>

<collision>
<origin rpy = '-1.570796327 3.141592654 0' xyz = '0.0 0.0 -0.32' />
<geometry> 
<mesh filename='package://cobot_bmw/meshes/lin_axis/carriage.stl' scale = '0.001 0.001 0.001' />
</geometry>
</collision>

</link>

<link name = 'segment1'>

</link>



<link name = 'segment1_blue'>
<visual>
<origin rpy = '0 -0.000000 0.000000' xyz = '0.0 0.0 0.0' />
<material name='Caerul'> 
<color rgba = '0.00 0.566 0.859 1.000000' />
</material><geometry> <mesh filename='package://cobot_bmw/meshes/v2_0_hull/segment01_blue.stl' scale='0.001000 0.001000 0.001000'/></geometry>
</visual>

<collision>
<origin rpy = '0 -0.000000 0.000000' xyz = '0.0 0.0 0.0' />
<geometry> <mesh filename='package://cobot_bmw/meshes/v2_0_hull/segment01_blue.stl' scale='0.001000 0.001000 0.001000'/></geometry>
</collision>

</link>

<link name = 'segment1_grey'>
<visual>
<origin rpy = '0 -0.000000 0.000000' xyz = '0.0 0.0 0.0' />
<material name='grey'> 
<color rgba = '0.309 0.324 0.344 1.000000' />
</material><geometry> <mesh filename='package://cobot_bmw/meshes/v2_0_hull/segment01_grey.stl' scale='0.001000 0.001000 0.001000'/></geometry>
</visual>

<collision>
<origin rpy = '0 -0.000000 0.000000' xyz = '0.0 0.0 0.0' />
<geometry> <mesh filename='package://cobot_bmw/meshes/v2_0_hull/segment01_grey.stl' scale='0.001000 0.001000 0.001000'/></geometry>
</collision>

</link>

<link name = 'segment1_silver'>
<visual>
<origin rpy = '0 -0.000000 0.000000' xyz = '0.0 0.0 0.0' />
<material name='silver'> 
<color rgba = '0.629 0.629 0.625 1.0' />
</material><geometry> <mesh filename='package://cobot_bmw/meshes/v2_0_hull/segment01_silver.stl' scale='0.001000 0.001000 0.001000'/></geometry>
</visual>

<collision>
<origin rpy = '0 -0.000000 0.000000' xyz = '0.0 0.0 0.0' />
<geometry> <mesh filename='package://cobot_bmw/meshes/v2_0_hull/segment01_silver.stl' scale='0.001000 0.001000 0.001000'/></geometry>
</collision>

</link>

<joint name = 'JFix_seg1_blue' type = 'fixed'>
<origin rpy = '-1.570793 -0.000000 3.141593' xyz = '0.000000 -0.311000 0.000000' />
  <parent link = 'segment1' />
  <child link = 'segment1_blue' />
</joint> 

<joint name = 'JFix_seg1_silver' type = 'fixed'>
<origin rpy = '-1.570793 -0.000000 3.141593' xyz = '0.000000 -0.311000 0.000000' />
  <parent link = 'segment1' />
  <child link = 'segment1_silver' />
</joint> 

<joint name = 'JFix_seg1_grey' type = 'fixed'>
<origin rpy = '-1.570793 -0.000000 3.141593' xyz = '0.000000 -0.311000 0.000000' />
  <parent link = 'segment1' />
  <child link = 'segment1_grey' />
</joint> 

<link name = 'segment2'>


</link>


<link name = 'segment2_black'>
<visual>
<origin rpy = '0 -0.000000 0.000000' xyz = '0.0 0.0 0.0' />
<material name='Aterul'> 
<color rgba = '0.055 0.055 0.0625 1.000000' />
</material><geometry> <mesh filename='package://cobot_bmw/meshes/v2_0_hull/segment02_black.stl' scale='0.001000 0.001000 0.001000'/></geometry>
</visual>

<collision>
<origin rpy = '0 -0.000000 0.000000' xyz = '0.0 0.0 0.0' />
<geometry> <mesh filename='package://cobot_bmw/meshes/v2_0_hull/segment02_black.stl' scale='0.001000 0.001000 0.001000'/></geometry>
</collision>

</link>


<link name = 'segment2_grey'>
<visual>
<origin rpy = '0 -0.000000 0.000000' xyz = '0.0 0.0 0.0' />
<material name='grey'> 
<color rgba = '0.309 0.324 0.344 1.000000' />
</material><geometry> <mesh filename='package://cobot_bmw/meshes/v2_0_hull/segment02_grey.stl' scale='0.001000 0.001000 0.001000'/></geometry>
</visual>

<collision>
<origin rpy = '0 -0.000000 0.000000' xyz = '0.0 0.0 0.0' />
<geometry> <mesh filename='package://cobot_bmw/meshes/v2_0_hull/segment02_grey.stl' scale='0.001000 0.001000 0.001000'/></geometry>
</collision>

</link>

<link name = 'segment2_silver'>
<visual>
<origin rpy = '0 -0.000000 0.000000' xyz = '0.0 0.0 0.0' />
<material name='silver'> 
<color rgba = '0.629 0.629 0.625 1.0' />
</material><geometry> <mesh filename='package://cobot_bmw/meshes/v2_0_hull/segment02_silver.stl' scale='0.001000 0.001000 0.001000'/></geometry>
</visual>

<collision>
<origin rpy = '0 -0.000000 0.000000' xyz = '0.0 0.0 0.0' />
<geometry> <mesh filename='package://cobot_bmw/meshes/v2_0_hull/segment02_silver.stl' scale='0.001000 0.001000 0.001000'/></geometry>
</collision>
</link>

<joint name = 'JFix_seg2_black' type = 'fixed'>
  <origin rpy = '0 0.000000 3.1415' xyz = '0.000000 0.000000 0.036000' /> 
  <parent link = 'segment2' />
  <child link = 'segment2_black' />
</joint> 

<joint name = 'JFix_seg2_grey' type = 'fixed'>
  <origin rpy = '0 0.000000 3.1415' xyz = '0.000000 0.000000 0.036000' /> 
  <parent link = 'segment2' />
  <child link = 'segment2_grey' />
</joint> 

<joint name = 'JFix_seg2_silver' type = 'fixed'>
  <origin rpy = '0 0.000000 3.1415' xyz = '0.000000 0.000000 0.036000' /> 
  <parent link = 'segment2' />
  <child link = 'segment2_silver' />
</joint> 

<link name = 'segment3'>


</link>


<link name = 'segment3_black'>

<visual>
<origin rpy = '0 -0.000000 0.000000' xyz = '0.0 0.0 0.0' />
<material name='Aterul'> 
<color rgba = '0.055 0.055 0.0625 1.000000' />
</material><geometry> <mesh filename='package://cobot_bmw/meshes/v2_0_hull/segment03_black.stl' scale='0.001000 0.001000 0.001000'/></geometry>
</visual>

<collision>
<origin rpy = '0 -0.000000 0.000000' xyz = '0.0 0.0 0.0' />
<geometry> <mesh filename='package://cobot_bmw/meshes/v2_0_hull/segment03_black.stl' scale='0.001000 0.001000 0.001000'/></geometry>
</collision>

</link>

<link name = 'segment3_blue'>

<visual>
<origin rpy = '0 -0.000000 0.000000' xyz = '0.0 0.0 0.0' />
<material name='Caerul'> 
<color rgba = '0.00 0.566 0.859 1.000000' />
</material><geometry> <mesh filename='package://cobot_bmw/meshes/v2_0_hull/segment03_blue.stl' scale='0.001000 0.001000 0.001000'/></geometry>
</visual>

<collision>
<origin rpy = '0 -0.000000 0.000000' xyz = '0.0 0.0 0.0' />
<geometry> <mesh filename='package://cobot_bmw/meshes/v2_0_hull/segment03_blue.stl' scale='0.001000 0.001000 0.001000'/></geometry>
</collision>

</link>

<link name = 'segment3_silver_2'>

<visual>
<origin rpy = '0 -0.000000 0.000000' xyz = '0.0 0.0 0.0' />
<material name='silver'> 
<color rgba = '0.629 0.629 0.625 1.0' />
</material>
<geometry> <mesh filename='package://cobot_bmw/meshes/v2_0_hull/segment03_silver_2.stl' scale='0.001000 0.001000 0.001000'/></geometry>
</visual>

<collision>
<origin rpy = '0 -0.000000 0.000000' xyz = '0.0 0.0 0.0' />
<geometry> <mesh filename='package://cobot_bmw/meshes/v2_0_hull/segment03_silver_2.stl' scale='0.001000 0.001000 0.001000'/></geometry>
</collision>

</link>

<link name = 'segment3_silver'>

<visual>
<origin rpy = '0 -0.000000 0.000000' xyz = '0.0 0.0 0.0' />
<material name='silver'> 
<color rgba = '0.629 0.629 0.625 1.0' />
</material><geometry> <mesh filename='package://cobot_bmw/meshes/v2_0_hull/segment03_silver.stl' scale='0.001000 0.001000 0.001000'/></geometry>
</visual>

<collision>
<origin rpy = '0 -0.000000 0.000000' xyz = '0.0 0.0 0.0' />
<geometry> <mesh filename='package://cobot_bmw/meshes/v2_0_hull/segment03_silver.stl' scale='0.001000 0.001000 0.001000'/></geometry>
</collision>

</link>

<joint name = 'JFix_seg3_black' type = 'fixed'>
  <origin rpy = '0 0.000000 3.1415' xyz = '+0.001000 +0.00000 0.06000' /> 
  <parent link = 'segment3' />
  <child link = 'segment3_black' />
</joint> 

<joint name = 'JFix_seg3_grey' type = 'fixed'>
  <origin rpy = '0 0.000000 3.1415' xyz = '+0.001000 +0.00000 0.06000' /> 
  <parent link = 'segment3' />
  <child link = 'segment3_silver_2' />
</joint> 

<joint name = 'JFix_seg3_silver' type = 'fixed'>
  <origin rpy = '0 0.000000 3.1415' xyz = '+0.001000 +0.00000 0.06000' /> 
  <parent link = 'segment3' />
  <child link = 'segment3_silver' />
</joint> 


<joint name = 'JFix_seg3_blue' type = 'fixed'>
  <origin rpy = '0 0.000000 3.1415' xyz = '+0.001000 +0.00000 0.06000' /> 
  <parent link = 'segment3' />
  <child link = 'segment3_blue' />
</joint> 

<link name = 'segment4'>

</link>


<link name = 'segment4_black'>
<visual>
<origin rpy = '0 -0.000000 0.000000' xyz = '0.0 0.0 0.0' />
<material name='Aterul'> 
<color rgba = '0.055 0.055 0.0625 1.000000' />
</material><geometry> <mesh filename='package://cobot_bmw/meshes/v2_0_hull/segment04_black.stl' scale='0.001000 0.001000 0.001000'/></geometry>
</visual>

<collision>
<origin rpy = '0 -0.000000 0.000000' xyz = '0.0 0.0 0.0' />
<geometry> <mesh filename='package://cobot_bmw/meshes/v2_0_hull/segment04_black.stl' scale='0.001000 0.001000 0.001000'/></geometry>
</collision>

</link>

<link name = 'segment4_blue'>
<visual>
<origin rpy = '0 -0.000000 0.000000' xyz = '0.0 0.0 0.0' />
<material name='Caerul'> 
<color rgba = '0.00 0.566 0.859 1.000000' />
</material><geometry> <mesh filename='package://cobot_bmw/meshes/v2_0_hull/segment04_blue.stl' scale='0.001000 0.001000 0.001000'/></geometry>
</visual>

<collision>
<origin rpy = '0 -0.000000 0.000000' xyz = '0.0 0.0 0.0' />
<geometry> <mesh filename='package://cobot_bmw/meshes/v2_0_hull/segment04_blue.stl' scale='0.001000 0.001000 0.001000'/></geometry>
</collision>

</link>

<link name = 'segment4_grey'>
<visual>
<origin rpy = '0 -0.000000 0.000000' xyz = '0.0 0.0 0.0' />
<material name='grey'> 
<color rgba = '0.309 0.324 0.344 1.000000' />
</material><geometry> <mesh filename='package://cobot_bmw/meshes/v2_0_hull/segment04_grey.stl' scale='0.001000 0.001000 0.001000'/></geometry>
</visual>

<collision>
<origin rpy = '0 -0.000000 0.000000' xyz = '0.0 0.0 0.0' />
<geometry> <mesh filename='package://cobot_bmw/meshes/v2_0_hull/segment04_grey.stl' scale='0.001000 0.001000 0.001000'/></geometry>
</collision>

</link>

<link name = 'segment4_silver'>
<visual>
<origin rpy = '0 -0.000000 0.000000' xyz = '0.0 0.0 0.0' />
<material name='silver'> 
<color rgba = '0.629 0.629 0.625 1.0' />
</material><geometry> <mesh filename='package://cobot_bmw/meshes/v2_0_hull/segment04_silver.stl' scale='0.001000 0.001000 0.001000'/></geometry>
</visual>

<collision>
<origin rpy = '0 -0.000000 0.000000' xyz = '0.0 0.0 0.0' />
<geometry> <mesh filename='package://cobot_bmw/meshes/v2_0_hull/segment04_silver.stl' scale='0.001000 0.001000 0.001000'/></geometry>
</collision>

</link>

<joint name = 'JFix_seg4_black' type = 'fixed'>
  <origin rpy = '3.1415 0.000000 -1.5707 ' xyz = '0.000000 0.000000 -0.035000' /> 
  <parent link = 'segment4' />
  <child link = 'segment4_black' />
</joint> 

<joint name = 'JFix_seg4_grey' type = 'fixed'>
  <origin rpy = '3.1415 0.000000 -1.5707 ' xyz = '0.000000 0.000000 -0.035000' /> 
  <parent link = 'segment4' />
  <child link = 'segment4_grey' />
</joint> 

<joint name = 'JFix_seg4_silver' type = 'fixed'>
  <origin rpy = '3.1415 0.000000 -1.5707 ' xyz = '0.000000 0.000000 -0.035000' /> 
  <parent link = 'segment4' />
  <child link = 'segment4_silver' />
</joint> 


<joint name = 'JFix_seg4_blue' type = 'fixed'>
  <origin rpy = '3.1415 0.000000 -1.5707 ' xyz = '0.000000 0.000000 -0.035000' /> 
  <parent link = 'segment4' />
  <child link = 'segment4_blue' />
</joint>


<link name = 'segment5'>

</link>

<link name = 'segment5_black'>

<visual>
<origin rpy = '0 -0.000000 0.000000' xyz = '0.0 0.0 0.0' />
<material name='Aterul'> 
<color rgba = '0.055 0.055 0.0625 1.000000' />
</material><geometry> <mesh filename='package://cobot_bmw/meshes/v2_0_hull/segment05_black.stl' scale='0.001000 0.001000 0.001000'/></geometry>
</visual>

<collision>
<origin rpy = '0 -0.000000 0.000000' xyz = '0.0 0.0 0.0' />
<geometry> <mesh filename='package://cobot_bmw/meshes/v2_0_hull/segment05_black.stl' scale='0.001000 0.001000 0.001000'/></geometry>
</collision>

</link>


<link name = 'segment5_grey'>

<visual>
<origin rpy = '0 -0.000000 0.000000' xyz = '0.0 0.0 0.0' />
<material name='grey'> 
<color rgba = '0.309 0.324 0.344 1.000000' />
</material><geometry> <mesh filename='package://cobot_bmw/meshes/v2_0_hull/segment05_grey.stl' scale='0.001000 0.001000 0.001000'/></geometry>
</visual>

<collision>
<origin rpy = '0 -0.000000 0.000000' xyz = '0.0 0.0 0.0' />
<geometry> <mesh filename='package://cobot_bmw/meshes/v2_0_hull/segment05_grey.stl' scale='0.001000 0.001000 0.001000'/></geometry>
</collision>

</link>

<joint name = 'JFix_seg5_black' type = 'fixed'>
<origin rpy = '0 -0.000000 3.1415' xyz = '0.0 -0.0 0.015' />
  <parent link = 'segment5' />
  <child link = 'segment5_black' />
</joint> 

<joint name = 'JFix_seg5_grey' type = 'fixed'>
<origin rpy = '0 -0.000000 3.1415' xyz = '0.0 -0.0 0.015' />
  <parent link = 'segment5' />
  <child link = 'segment5_grey' />
</joint> 



<link name = 'segment6'>


</link>


<link name = 'segment6_black'>

<visual>
<origin rpy = '0 -0.000000 0.000000' xyz = '0.0 0.0 0.0' />
<material name='Aterul'> 
<color rgba = '0.055 0.055 0.0625 1.000000' />
</material><geometry> <mesh filename='package://cobot_bmw/meshes/v2_0_hull/segment06_black.stl' scale='0.001000 0.001000 0.001000'/></geometry>
</visual>

<collision>
<origin rpy = '0 -0.000000 0.000000' xyz = '0.0 0.0 0.0' />
<geometry> <mesh filename='package://cobot_bmw/meshes/v2_0_hull/segment06_black.stl' scale='0.001000 0.001000 0.001000'/></geometry>
</collision>

</link>

<link name = 'segment6_blue'>

<visual>
<material name='Caerul'> 
<color rgba = '0.00 0.566 0.859 1.000000' />
</material><geometry> <mesh filename='package://cobot_bmw/meshes/v2_0_hull/segment06_blue.stl' scale='0.001000 0.001000 0.001000'/></geometry>
</visual>

<collision>
<origin rpy = '0 -0.000000 0.000000' xyz = '0.0 0.0 0.0' />
<geometry> <mesh filename='package://cobot_bmw/meshes/v2_0_hull/segment06_blue.stl' scale='0.001000 0.001000 0.001000'/></geometry>
</collision>

</link>

<link name = 'segment6_grey'>

<visual>
<origin rpy = '0 -0.000000 0.000000' xyz = '0.0 0.0 0.0' />
<material name='grey'> 
<color rgba = '0.309 0.324 0.344 1.000000' />
</material><geometry> <mesh filename='package://cobot_bmw/meshes/v2_0_hull/segment06_grey.stl' scale='0.001000 0.001000 0.001000'/></geometry>
</visual>

<collision>
<origin rpy = '0 -0.000000 0.000000' xyz = '0.0 0.0 0.0' />
<geometry> <mesh filename='package://cobot_bmw/meshes/v2_0_hull/segment06_grey.stl' scale='0.001000 0.001000 0.001000'/></geometry>
</collision>

</link>

<link name = 'segment6_silver'>

<visual>
<origin rpy = '0 -0.000000 0.000000' xyz = '0.0 0.0 0.0' />
<material name='silver'> 
<color rgba = '0.629 0.629 0.625 1.0' />
</material><geometry> <mesh filename='package://cobot_bmw/meshes/v2_0_hull/segment06_silver.stl' scale='0.001000 0.001000 0.001000'/></geometry>
</visual>

<collision>
<origin rpy = '0 -0.000000 0.000000' xyz = '0.0 0.0 0.0' />
<geometry> <mesh filename='package://cobot_bmw/meshes/v2_0_hull/segment06_silver.stl' scale='0.001000 0.001000 0.001000'/></geometry>
</collision>

</link>
<joint name = 'JFix_seg6_black' type = 'fixed'>
  <origin rpy = '0 0.000000 -1.5708' xyz = '0.005000 -0.000000 0.038' /> 
  <parent link = 'segment6' />
  <child link = 'segment6_black' />
</joint> 

<joint name = 'JFix_seg6_grey' type = 'fixed'>
  <origin rpy = '0 0.000000 -1.5708' xyz = '0.005000 -0.000000 0.038' /> 
  <parent link = 'segment6' />
  <child link = 'segment6_grey' />
</joint> 


<joint name = 'JFix_seg6_blue' type = 'fixed'>
  <origin rpy = '0 0.000000 -1.5708' xyz = '0.005000 -0.000000 0.038' /> 
  <parent link = 'segment6' />
  <child link = 'segment6_blue' />
</joint>


<joint name = 'JFix_seg6_silver' type = 'fixed'>
  <origin rpy = '0 0.000000 -1.5708' xyz = '0.005000 -0.000000 0.038' /> 
  <parent link = 'segment6' />
  <child link = 'segment6_silver' />
</joint> 

<link name = 'segment7'>
</link>


<link name = 'segment7_black'>

<visual>
<origin rpy = '0 -0.000000 0.000000' xyz = '0.0 0.0 0.0' />
<material name='Aterul'> 
<color rgba = '0.055 0.055 0.0625 1.000000' />
</material><geometry> <mesh filename='package://cobot_bmw/meshes/v2_0_hull/segment07_black.stl' scale='0.001000 0.001000 0.001000'/></geometry>
</visual>

<collision>
<origin rpy = '0 -0.000000 0.000000' xyz = '0.0 0.0 0.0' />
<geometry> <mesh filename='package://cobot_bmw/meshes/v2_0_hull/segment07_black.stl' scale='0.001000 0.001000 0.001000'/></geometry>
</collision>

</link>

<link name = 'segment7_silver'>

<visual>
<origin rpy = '0 -0.000000 0.000000' xyz = '0.0 0.0 0.0' />
<material name='silver'> 
<color rgba = '0.629 0.629 0.625 1.0' />
</material><geometry> <mesh filename='package://cobot_bmw/meshes/v2_0_hull/segment07_silver.stl' scale='0.001000 0.001000 0.001000'/></geometry>
</visual>

</link>


<joint name = 'JFix_seg7_black' type = 'fixed'>
  <origin rpy = '0 0.000000 0.000000' xyz = '0.004000 0.002000 0.091000' /> 
  <parent link = 'segment7' />
  <child link = 'segment7_black' />
</joint> 

<joint name = 'JFix_seg7_silver' type = 'fixed'>
  <origin rpy = '0 0.000000 0.000000' xyz = '0.004000 0.002000 0.09100' /> 
  <parent link = 'segment7' />
  <child link = 'segment7_silver' />
</joint> 

<link name = 'TCP'>
<visual>
<origin xyz="-0.005 -0.002 0.010" rpy = "0 0 0" />
<geometry>
  <cylinder radius="0.00001" length="0.000001" />
</geometry>
<material name='silver'>
<color rgba = '0.629 0.629 0.625 1.0' />
</material>
</visual>


<!-- Joints -->

<joint name = 'joint_0' type = 'prismatic'>
    <origin rpy = '0 0 0' xyz = '0.000000 0.0000 0.000000' />
    <parent link = 'lin_axis' />
    <child link = 'lin_axis_carriage' />
    <axis xyz = '0 1 0' />
    <limit 
    effort = '20.000'
    velocity = '3.141593'
    lower = '-.35' 
    upper = '.55' />
</joint> 

<joint name = 'mount_fixture' type = 'fixed'>
    <origin rpy = '0 0 0' xyz = '0.000000 0.0000 0.000000' />
    <parent link = 'lin_axis_carriage' />
    <child link = 'segment1' />
</joint> 

<joint name = 'joint_1' type = 'revolute'>
  <origin rpy = '-1.570793 -0.000000 3.141593' xyz = '0.000000 -0.274400 0.000000' /> 
  <parent link = 'segment1' />
  <child link = 'segment2' />
  <axis xyz = '0 0 1' />
  <limit effort = '40.000000'
        velocity = '3.141593'
lower = '-0.7853976732051033' upper = '3.9269903267948965'  
/>  <dynamics damping = '0' friction = '0' /> 

 </joint > 
 


<joint name = 'joint_2' type = 'revolute'>
  <origin rpy = '-1.570796 -0.000000 0.000000' xyz = '0.000050 0.049550 0.155500' /> 
  <parent link = 'segment2' />
  <child link = 'segment3' />
  <axis xyz = '0 0 1' />
  <limit effort = '20.000000'
        velocity = '3.141593'
lower = '-1.570796' upper = '1.570796'  
/>  <dynamics damping = '0' friction = '0' /> 

 </joint > 
 


<joint name = 'joint_3' type = 'revolute'>
  <origin rpy = '3.141593 0.000000 1.570796' xyz = '-0.254493 0.000000 0.085200' /> 
  <parent link = 'segment3' />
  <child link = 'segment4' />
  <axis xyz = '0 0 1' />
  <limit effort = '10.000000'
        velocity = '3.141593'
lower = '-1.570796' upper = '1.570796'  
/>  <dynamics damping = '0' friction = '0' /> 

 </joint > 
 


<joint name = 'joint_4' type = 'revolute'>
  <origin rpy = '-1.570796 0.000000 -3.141593' xyz = '0.000000 -0.007600 0.132393' /> 
  <parent link = 'segment4' />
  <child link = 'segment5' />
  <axis xyz = '0 0 1' />
  <limit effort = '10.000000'
        velocity = '3.141593'
lower = '-1.570796' upper = '1.570796'  
/>  <dynamics damping = '0' friction = '0' /> 

 </joint > 
 


<joint name = 'joint_5' type = 'revolute'>
  <origin rpy = '-1.570796 -0.000000 3.141593' xyz = '0.000000 -0.006300 0.113264' /> 
  <parent link = 'segment5' />
  <child link = 'segment6' />
  <axis xyz = '0 0 1' />
  <limit effort = '5.000000'
        velocity = '3.141593'
lower = '-1.570796' upper = '1.570796'  
/>  <dynamics damping = '0' friction = '0' /> 

 </joint > 
 


<joint name = 'joint_6' type = 'revolute'>
  <origin rpy = '1.570796 -0.000000 -0.000000' xyz = '-0.000000 -0.132800 -0.006164' /> 
  <parent link = 'segment6' />
  <child link = 'segment7' />
  <axis xyz = '0 0 1' />
  <limit effort = '5.000000'
        velocity = '3.141593'
lower = '-2.356194' upper = '2.356194'  
/>  <dynamics damping = '0' friction = '0' /> 

 </joint >



<joint name = 'JFix_TCP' type = 'fixed'>
  <origin rpy = '-0.000000 -0.000000 3.141593' xyz = '0.000000 0.000000 0.190143' />
  <parent link = 'segment7' />
  <child link = 'TCP' />
</joint> 
 


<joint name = 'JFix_Base' type = 'fixed'>
  <origin rpy = '-1.570796 0.000000 0.000000' xyz = '0.000000 0.000000 0.000000' /> 
  <parent link = 'base_link' />
  <child link = 'lin_axis' />
</joint> 

</robot>
