<?xml version="1.0" ?>
<robot xmlns:xacro="http://www.ros.org/wiki/xacro">
    <link name="world" />
    <joint name="robot_in_world" type="fixed">
        <origin xyz="0.0 0.0 0.0" rpy="0.0 0.0 0.0" />
        <parent link="world" />
        <child link="base_link" />
        <axis xyz="0 0 1" />
    </joint>
    <!-- Links -->
    <link name="base_link" />
    <link name="lin_axis">
        <visual>
            <origin rpy="0.0 0.0 0.0" xyz="0.0 0.0 0.0" />
            <geometry>
                <mesh filename="package://cobot_model/meshes/visual/axis_visual.dae" scale="0.001 0.001 0.001" />
                <material name="silver">
                    <color rgba="1.0 1.0 1.0 1.0" />
                </material>
            </geometry>
        </visual>
        <collision>
            <origin rpy="0.0 0.0 0.0" xyz="0.0 0.0 0.0" />
            <geometry>
                <mesh filename="package://cobot_model/meshes/collision/axis_collision.dae" scale="0.001 0.001 0.001" />
            </geometry>
        </collision>
        <inertial>
            <mass value="8.6" />
            <origin rpy="0.0 0.0 0.0" xyz="0.0 0.0 0.6" />
            <inertia ixx="1.03466672" iyy="1.0433778" izz="0.01404452" ixy="0.0" ixz="0.0" iyz="0.0" />
        </inertial>
    </link>
    <link name="lin_axis_carriage">
        <visual>
             <origin rpy="0.0 0.0 0.0" xyz="0.0 0.0 0.0" />
            <geometry>
                <mesh filename="package://cobot_model/meshes/visual/carriage_visual.dae" scale="0.001 0.001 0.001" />
                <material name="silver">
                    <color rgba="1.0 1.0 1.0 1.0" />
                </material>
            </geometry>
        </visual>
        <collision>
             <origin rpy="0.0 0.0 0.0" xyz="0.0 0.0 0.0" />
            <geometry>
                <mesh filename="package://cobot_model/meshes/collision/carriage_collision.dae" scale="0.001 0.001 0.001" />
            </geometry>
        </collision>
        <inertial>
            <mass value="0.7" />
            <origin rpy="0.0 0.0 0.0" xyz="0.0 0.0 0.11" />
            <inertia ixx="0.00287479" iyy="0.00415339" izz="0.00138151" ixy="0.0" ixz="0.0" iyz="0.0" />
        </inertial>
    </link>
    <link name="segment1">
        <visual>
             <origin rpy="0.0 0.0 0.0" xyz="0.0 0.0 0.0" />
            <geometry>
                <mesh filename="package://cobot_model/meshes/visual/segment01_visual.stl" scale="0.001 0.001 0.001" />
            </geometry>
            <material name="segment1_material">
                <color rgba="0.89 0.133 0.098 1.0" />
            </material>
        </visual>
        <collision>
            <origin rpy="0.0 0.0 0.0" xyz="0.0 0.0 0.0" />
            <geometry>
                <mesh filename="package://cobot_model/meshes/collision/segment01_collision.stl" scale="0.001 0.001 0.001" />
            </geometry>
        </collision>
        <inertial>
            <mass value="7.3" />
             <origin rpy="0.0 0.0 0.0" xyz="0.0 0.0 -0.156" />
            <inertia ixx="0.0697588" iyy="0.0697588" izz="0.0210824" ixy="0.0" ixz="0.0" iyz="0.0" />
        </inertial>
    </link>
    <link name="segment2">
        <visual>
            <origin rpy="0.0 0.0 0.0" xyz="0.0 0.0 0.0" />
            <geometry>
                <mesh filename="package://cobot_model/meshes/visual/segment02_visual.stl" scale="0.001 0.001 0.001" />
            </geometry>
            <material name="segment2_material">
                <color rgba="1.0 1.0 1.0 1.0" />
            </material>
        </visual>
        <collision>
            <origin rpy="0.0 0.0 0.0" xyz="0.0 0.0 0.0" />
            <geometry>
                <mesh filename="package://cobot_model/meshes/collision/segment02_collision.stl" scale="0.001 0.001 0.001" />
            </geometry>
        </collision>
        <inertial>
            <mass value="5.0" />
            <origin rpy="0.0 0.0 0.0" xyz="0.0 0.0 0.119" />
            <inertia ixx="0.03441292" iyy="0.02442542" izz="0.03361208" ixy="0.0" ixz="0.0" iyz="0.0" />
        </inertial>
    </link>
    <link name="segment3">
        <visual>
            <origin rpy="0.0 0.0 0.0" xyz="0.0 0.0 0.0" />
            <geometry>
                <mesh filename="package://cobot_model/meshes/visual/segment03_visual.stl" scale="0.001 0.001 0.001" />
            </geometry>
            <material name="segment3_material">
                <color rgba="0.89 0.133 0.098 1.0" />
            </material>
        </visual>
        <collision>
            <origin rpy="0.0 0.0 0.0" xyz="0.0 0.0 0.0" />
            <geometry>
                <mesh filename="package://cobot_model/meshes/collision/segment03_collision.stl" scale="0.001 0.001 0.001" />
            </geometry>
        </collision>
        <inertial>
            <mass value="2.5" />
            <origin rpy="0.0 0.0 0.0" xyz="0.126 0.0 0.06" />
            <inertia ixx="0.01325083" ixy="0.0" ixz="-0.0189" iyy="0.06515833" iyz="0.0" izz="0.05607417" />
        </inertial>
    </link>
    <link name="segment4">
        <visual>
            <origin rpy="0.0 0.0 0.0" xyz="0.0 0.0 0.0" />
            <geometry>
                <mesh filename="package://cobot_model/meshes/visual/segment04_visual.stl" scale="0.001 0.001 0.001" />
            </geometry>
            <material name="segment4_material">
                <color rgba="0.89 0.133 0.098 1.0" />
            </material>
        </visual>
        <collision>
             <origin rpy="0.0 0.0 0.0" xyz="0.0 0.0 0.0" />
            <geometry>
                <mesh filename="package://cobot_model/meshes/collision/segment04_collision.stl" scale="0.001 0.001 0.001" />
            </geometry>
        </collision>
        <inertial>
            <mass value="3.4" />
            <origin rpy="0.0 0.0 0.0" xyz="0.0 0.0 -0.112" />
            <inertia ixx="0.01850875" ixy="0.0" ixz="0.0" iyy="0.01850875" iyz="0.0" izz="0.00833" />
        </inertial>
    </link>
    <link name="segment5">
        <visual>
            <origin rpy="0.0 0.0 0.0" xyz="0.0 0.0 0.0" />
            <geometry>
                <mesh filename="package://cobot_model/meshes/visual/segment05_visual_big.stl" scale="0.001 0.001 0.001" />
            </geometry>
            <material name="segment5_material">
                <color rgba="1.0 0.929 0.0 1.0" />
            </material>
        </visual>
        <collision>
            <origin rpy="0.0 0.0 0.0" xyz="0.0 0.0 0.0" />
            <geometry>
                <mesh filename="package://cobot_model/meshes/collision/segment05_collision_big.stl" scale="0.001 0.001 0.001" />
            </geometry>
        </collision>
        <inertial>
            <mass value="1.1" />
            <origin rpy="0.0 0.0 0.0" xyz="0.0 0.0 0.071" />
            <inertia ixx="0.00623544" iyy="0.00623544" izz="0.00277255" ixy="0.0" ixz="0.0" iyz="0.0" />
        </inertial>
    </link>
    <link name="segment6">
        <visual>
            <origin rpy="0.0 0.0 0.0" xyz="0.0 0.0 0.0" />
            <geometry>
                <mesh filename="package://cobot_model/meshes/visual/segment06_visual_small.stl" scale="0.001 0.001 0.001" />
            </geometry>
            <material name="segment6_material">
                <color rgba="1.0 1.0 1.0 1.0" />
            </material>
        </visual>
        <collision>
            <origin rpy="0.0 0.0 0.0" xyz="0.0 0.0 0.0" />
            <geometry>
                <mesh filename="package://cobot_model/meshes/collision/segment06_collision_small.stl" scale="0.001 0.001 0.001" />
            </geometry>
        </collision>
        <inertial>
            <mass value="1.5" />
            <origin rpy="0.0 0.0 0.0" xyz="0.05 0.0 0.0" />
            <inertia ixx="0.00319363" iyy="0.00513113" izz="0.0061625" ixy="0.0" ixz="0.0" iyz="0.0" />
        </inertial>
    </link>
      <link name="segment7">
        <visual>
            <origin rpy="0.0 0.0 0.0" xyz="0.0 0.0 0.0"/>
            <material name="Aterul">
                <color rgba="1.0 1.0 1.0 1.0"/>
            </material>
            <geometry>
                <mesh filename="package://cobot_model/meshes/visual/segment07_real_visual.stl" scale="0.001 0.001 0.001"/>
            </geometry>
        </visual>
        <collision>
            <origin rpy="0.0 0.0 0.0" xyz="0.0 0.0 0.0"/>
            <geometry>
                <mesh filename="package://cobot_model/meshes/collision/segment07_real_collision.stl" scale="0.001 0.001 0.001"/>
            </geometry>
        </collision>
        <inertial>
            <mass value="4.0"/>
            <origin rpy="0.0 0.0 0.0" xyz="0.0 -0.09 0.04"/>
           <inertia ixx="0.02693367" iyy="0.01533367" izz="0.02185067" ixy="0.0" ixz="0.0" iyz="0.0" />
        </inertial>
  </link>
    <link name="TCP">
        <visual>
            <origin rpy="0.0 0.0 0.0" xyz="0.0 0.0 0.0" />
            <geometry>
                <cylinder radius="0.00001" length="0.000001" />
            </geometry>
            <material name="silver">
                <color rgba="0.629 0.629 0.625 1.0" />
            </material>
        </visual>
        <collision>
            <origin rpy="0.0 0.0 0.0" xyz="-0.12 -0.03 0.0"/>
            <geometry>
                <cylinder radius="0.00001" length="0.00001" />
            </geometry>
        </collision>
    </link> 
    <link name="finger1">
        <visual>
           <origin rpy="0.0 0.0 0.0" xyz="0.0 0.08 -0.06"/>
            <material name="silver">
                <color rgba="0.629 0.629 0.625 1.0" />
            </material>
            <geometry>
                <mesh filename="package://cobot_model/meshes/visual/finger01_real_visual.stl" scale="0.001 0.001 0.001" />
            </geometry>
        </visual>
        <collision>
            <origin rpy="0.0 0.0 0.0" xyz="0.0 0.08 -0.06"/>
            <geometry>
                <mesh filename="package://cobot_model/meshes/collision/finger01_real_collision.stl" scale="0.001 0.001 0.001" />
            </geometry>
        </collision>
        <inertial>
            <mass value="0.05" />
            <origin rpy="-0.785 0.0 0.0" xyz="0.02 0.03 0.03" />
            <inertia ixx="3.46666667e-05" iyy="2.64166667e-05" izz="1.78833333e-05" ixy="0.0" ixz="0.0" iyz="0.0" />
        </inertial>
    </link>
    <link name="finger2">
        <visual>
            <origin rpy="0.0 0.0 0.0" xyz="0.0 0.08 -0.06"/>
            <material name="silver">
                <color rgba="0.629 0.629 0.625 1.0" />
            </material>
            <geometry>
                <mesh filename="package://cobot_model/meshes/visual/finger02_real_visual.stl" scale="0.001 0.001 0.001" />
            </geometry>
        </visual>
        <collision>
            <origin rpy="0.0 0.0 0.0" xyz="0.0 0.08 -0.06"/>
            <geometry>
                <mesh filename="package://cobot_model/meshes/collision/finger02_real_collision.stl" scale="0.001 0.001 0.001" />
            </geometry>
        </collision>
        <inertial>
            <mass value="0.05" />
            <origin rpy="-0.785 0.0 0.0" xyz="-0.02 0.03 0.03" />
            <inertia ixx="3.46666667e-05" iyy="2.64166667e-05" izz="1.78833333e-05" ixy="0.0" ixz="0.0" iyz="0.0" />
        </inertial>
    </link>

    <!-- Joints -->
    <joint name="joint_0" type="prismatic">
        <origin rpy="0.0 0.0 0.0" xyz="0.0 0.0 0.3" />
        <parent link="lin_axis" />
        <child link="lin_axis_carriage" />
        <axis xyz="0 0 1" />
        <limit effort="300.0" velocity="3.141593" lower="-.35" upper=".55" />
    </joint>
    <joint name="mount_fixture" type="fixed">
        <origin rpy="0.0 0.0 0.0" xyz="0.0 0.3 0.3" />
        <parent link="lin_axis_carriage" />
        <child link="segment1" />
    </joint>
    <joint name="joint_1" type="revolute">
        <origin rpy="0.0 0.0 0.0" xyz="0.0 0.0 0.0" />
        <parent link="segment1" />
        <child link="segment2" />
        <axis xyz="0 0 1" />
        <limit effort="200.0" velocity="3.141593" lower="-0.7853976732051033" upper="3.9269903267948965" />
        <dynamics damping="0.0" friction="0.0" />
    </joint>
    <joint name="joint_2" type="revolute">
        <origin rpy="1.5708 0.0 0.0" xyz="0.0 -0.111 0.118" />
        <parent link="segment2" />
        <child link="segment3" />
        <axis xyz="0 0 1" />
        <limit effort="150.0" velocity="3.141593" lower="-0.9" upper="1.570796" />
        <dynamics damping="0.0" friction="0.0" />
    </joint>
    <joint name="joint_3" type="revolute">
        <origin rpy="0.0 0.0 0.0" xyz="0.254 0.0 0.06" />
        <parent link="segment3" />
        <child link="segment4" />
        <axis xyz="0 0 1" />
        <limit effort="100.0" velocity="3.141593" lower="-1.570796" upper="1.570796" />
        <dynamics damping="0.0" friction="0.0" />
    </joint>
    <joint name="joint_4" type="revolute">
        <origin rpy="-1.5708 0.0 -1.5708" xyz="0.024 0.0 -0.168" />
        <parent link="segment4" />
        <child link="segment5" />
        <axis xyz="0 0 1" />
        <limit effort="50.0" velocity="3.141593" lower="-1.570796" upper="1.570796" />
        <dynamics damping="0.0" friction="0.0" />
    </joint>
    <joint name="joint_5" type="revolute">
        <origin rpy="-1.570 -1.570 0.0" xyz="0.0 0.042 0.193" />
        <parent link="segment5" />
        <child link="segment6" />
        <axis xyz="0 0 1" />
        <limit effort="50.0" velocity="3.141593" lower="-1.570796" upper="1.570796" />
        <dynamics damping="0.0" friction="0.0" />
    </joint>
    <joint name="joint_6" type="revolute">
        <origin rpy="0.0 1.57 0.0" xyz="0.156 0.0 -0.04"/>
        <parent link="segment6"/>
        <child link="segment7"/>
        <axis xyz="0 0 1"/>
        <limit effort="20." lower="-2.356194" upper="2.356194" velocity="3.141593"/>
        <dynamics damping="0.0" friction="0.0"/>
    </joint>
    <joint name="JFix_TCP" type="fixed">
        <origin rpy="-0.785 0.0 0.0" xyz="0.0 -0.08 0.06"/>
        <parent link="segment7"/>
        <child link="TCP"/>
    </joint>
   <joint name="JFix_Base" type="fixed">
        <origin rpy="0.0 0.0 0.0" xyz="0.0 0.0 0.0" />
        <parent link="base_link" />
        <child link="lin_axis" />
    </joint>
    <joint name="finger1_joint" type="prismatic">
        <origin rpy="0.785 0.0 0.0" xyz="0.0 0.0 0.0" />
        <parent link="TCP" />
        <child link="finger1" />
        <axis xyz="-1 0 0" />
        <limit effort="30.0" velocity="0.1" lower="-0.01" upper="0.015" />
    </joint>
    <joint name="finger2_joint" type="prismatic">
        <origin rpy="0.785 0.0 0.0" xyz="0.0 0.0 0.0" />
        <parent link="TCP" />
        <child link="finger2" />
        <axis xyz="1 0 0" />
        <limit effort="30.0" velocity="0.1" lower="-0.01" upper="0.015" />
        <mimic joint="finger1_joint" />
    </joint>
</robot>