<?xml version="1.0" ?>
<robot xmlns:xacro="http://www.ros.org/wiki/xacro">

    <xacro:arg name="use_collision_meshes" default="true" />

    <link name="world" />
    <joint name="robot_in_world" type="fixed">
        <origin xyz="0.0 0.0 0.0" rpy="0.0 0.0 0.0" />
        <parent link="world" />
        <child link="base_link" />
        <axis xyz="0 0 1" />
    </joint>
    <!-- Links -->
    <link name="base_link" />
    <link name="lin_axis">
        <visual>
            <origin rpy="0.0 0.0 0.0" xyz="0.0 0.0 0.0" />
            <geometry>
                <mesh filename="package://cobot_model/meshes/visual/axis_visual.dae" scale="0.001 0.001 0.001" />
                <material name="silver">
                    <color rgba="1.0 1.0 1.0 1.0" />
                </material>
            </geometry>
        </visual>
        <collision>
            <xacro:if value="${'$(arg use_collision_meshes)' == 'true'}">
                <origin rpy="0.0 0.0 0.0" xyz="0.0 0.0 0.0" />
                <geometry>
                    <mesh filename="package://cobot_model/meshes/collision/axis_collision.dae" scale="0.001 0.001 0.001" />
                </geometry>
            </xacro:if>
            <xacro:unless value="${'$(arg use_collision_meshes)' == 'true'}">
                <origin rpy="0.0 0.0 0.0" xyz="0.0 0.03 0.6"/>
                <geometry>
                    <box size="0.162 0.069 1.21"/>
                </geometry>
            </xacro:unless>
        </collision>
        <inertial>
            <mass value="8.6" />
            <origin rpy="0.0 0.0 0.0" xyz="0.0 0.0 0.6" />
            <inertia ixx="1.03466672" iyy="1.0433778" izz="0.01404452" ixy="0.0" ixz="0.0" iyz="0.0" />
        </inertial>
    </link>
    <link name="lin_axis_carriage">
        <visual>
             <origin rpy="0.0 0.0 0.0" xyz="0.0 0.0 0.0" />
            <geometry>
                <mesh filename="package://cobot_model/meshes/visual/carriage_real_visual.dae" scale="0.001 0.001 0.001" />
                <material name="silver">
                    <color rgba="1.0 1.0 1.0 1.0" />
                </material>
            </geometry>
        </visual>
        <collision>
            <xacro:if value="${'$(arg use_collision_meshes)' == 'true'}">
                <origin rpy="0.0 0.0 0.0" xyz="0.0 0.0 0.0" />
                <geometry>
                   <mesh filename="package://cobot_model/meshes/visual/carriage_real_visual.dae" scale="0.001 0.001 0.001" />
                </geometry>
            </xacro:if>
            <xacro:unless value="${'$(arg use_collision_meshes)' == 'true'}">
                <origin rpy="0.0 0.0 0.0" xyz="0.06 0.26 0.2"/>
                <geometry>
                    <box size="0.302 0.431 0.02"/>
                </geometry>
            </xacro:unless>
        </collision>
        <inertial>
            <mass value="0.7" />
            <origin rpy="0.0 0.0 0.0" xyz="0.0 0.0 0.11" />
            <inertia ixx="0.00287479" iyy="0.00415339" izz="0.00138151" ixy="0.0" ixz="0.0" iyz="0.0" />
        </inertial>
    </link>
    <link name="segment1">
        <visual>
             <origin rpy="0.0 0.0 0.0" xyz="0.0 0.0 0.0" />
            <geometry>
                <mesh filename="package://cobot_model/meshes/visual/segment_01_logo.dae" scale="0.001 0.001 0.001" />
            </geometry>
            <material name="segment1_material">
                <color rgba="0.89 0.133 0.098 1.0" />
            </material>
        </visual>
        <collision>
            <xacro:if value="${'$(arg use_collision_meshes)' == 'true'}">
                <origin rpy="0.0 0.0 0.0" xyz="0.0 0.0 0.0" />
                <geometry>
                    <mesh filename="package://cobot_model/meshes/collision/segment01_collision.stl" scale="0.001 0.001 0.001" />
                </geometry>
            </xacro:if>
            <xacro:unless value="${'$(arg use_collision_meshes)' == 'true'}">
            <origin rpy="0.0 0.0 0.0" xyz="0.0 0.0 -0.156"/>
                <geometry>
                    <cylinder radius="0.09" length="0.312"/>
                </geometry>
            </xacro:unless>
        </collision>
        <inertial>
            <mass value="7.3" />
             <origin rpy="0.0 0.0 0.0" xyz="0.0 0.0 -0.156" />
            <inertia ixx="0.0697588" iyy="0.0697588" izz="0.0210824" ixy="0.0" ixz="0.0" iyz="0.0" />
        </inertial>
    </link>
    <link name="segment2">
        <visual>
            <origin rpy="0.0 0.0 0.0" xyz="0.0 0.0 0.0" />
            <geometry>
                <mesh filename="package://cobot_model/meshes/visual/segment02_visual.stl" scale="0.001 0.001 0.001" />
            </geometry>
            <material name="segment2_material">
                <color rgba="0 0.6 1.0 1.0" />
            </material>
        </visual>
        <collision>
            <xacro:if value="${'$(arg use_collision_meshes)' == 'true'}">
                <origin rpy="0.0 0.0 0.0" xyz="0.0 0.0 0.0" />
                <geometry>
                    <mesh filename="package://cobot_model/meshes/collision/segment02_collision.stl" scale="0.001 0.001 0.001" />
                </geometry>
            </xacro:if>
            <xacro:unless value="${'$(arg use_collision_meshes)' == 'true'}">
                <origin rpy="0.0 0.0 0.0" xyz="0.0 0.0 0.09"/>
                <geometry>
                    <box size="0.155 0.238 0.186"/>
                </geometry>
            </xacro:unless>
        </collision>
        <inertial>
            <mass value="5.0" />
            <origin rpy="0.0 0.0 0.0" xyz="0.0 0.0 0.119" />
            <inertia ixx="0.03441292" iyy="0.02442542" izz="0.03361208" ixy="0.0" ixz="0.0" iyz="0.0" />
        </inertial>
    </link>
    <link name="segment3">
        <visual>
            <origin rpy="0.0 0.0 0.0" xyz="0.0 0.0 0.0" />
            <geometry>
                <mesh filename="package://cobot_model/meshes/visual/segment03_visual.stl" scale="0.001 0.001 0.001" />
            </geometry>
            <material name="segment3_material">
               <color rgba="0.835 0.059 0.235 1.0" />
            </material>
        </visual>
        <collision>
            <xacro:if value="${'$(arg use_collision_meshes)' == 'true'}">
                <origin rpy="0.0 0.0 0.0" xyz="0.0 0.0 0.0" />
                <geometry>
                    <mesh filename="package://cobot_model/meshes/collision/segment03_collision.stl" scale="0.001 0.001 0.001" />
                </geometry>
            </xacro:if>
            <xacro:unless value="${'$(arg use_collision_meshes)' == 'true'}">
                <origin rpy="0.0 1.57 0.0" xyz="0.126 0.0 0.06"/>
                <geometry>
                    <cylinder radius="0.06" length="0.372"/>
                </geometry>
            </xacro:unless>
        </collision>
        <inertial>
            <mass value="2.5" />
            <origin rpy="0.0 0.0 0.0" xyz="0.126 0.0 0.06" />
            <inertia ixx="0.01325083" ixy="0.0" ixz="-0.0189" iyy="0.06515833" iyz="0.0" izz="0.05607417" />
        </inertial>
    </link>
    <link name="segment4">
        <visual>
            <origin rpy="0.0 0.0 0.0" xyz="0.0 0.0 0.0" />
            <geometry>
                <mesh filename="package://cobot_model/meshes/visual/segment04_visual.stl" scale="0.001 0.001 0.001" />
            </geometry>
            <material name="segment4_material">
                <color rgba="0.004 0.176 0.353 1.0" />
            </material>
        </visual>
        <collision>
            <xacro:if value="${'$(arg use_collision_meshes)' == 'true'}">
                <origin rpy="0.0 0.0 0.0" xyz="0.0 0.0 0.0" />
                <geometry>
                    <mesh filename="package://cobot_model/meshes/collision/segment04_collision.stl" scale="0.001 0.001 0.001" />
                </geometry>
            </xacro:if>
            <xacro:unless value="${'$(arg use_collision_meshes)' == 'true'}">
                <origin rpy="0.0 0.0 0.0" xyz="0.0 0.0 -0.1125"/>
                <geometry>
                    <cylinder radius="0.07" length="0.225"/>
                </geometry>
            </xacro:unless>
        </collision>
        <inertial>
            <mass value="3.4" />
            <origin rpy="0.0 0.0 0.0" xyz="0.0 0.0 -0.112" />
            <inertia ixx="0.01850875" ixy="0.0" ixz="0.0" iyy="0.01850875" iyz="0.0" izz="0.00833" />
        </inertial>
    </link>
    <link name="segment5">
        <visual>
            <origin rpy="0.0 0.0 0.0" xyz="0.0 0.0 0.0" />
            <geometry>
                <mesh filename="package://cobot_model/meshes/visual/segment05_power_visual.stl" scale="0.001 0.001 0.001" />
            </geometry>
            <material name="segment5_material">
                <color rgba="0 0.6 1.0 1.0" />
            </material>
        </visual>
        <collision>
            <xacro:if value="${'$(arg use_collision_meshes)' == 'true'}">
                <origin rpy="0.0 0.0 0.0" xyz="0.0 0.0 0.0" />
                <geometry>
                    <mesh filename="package://cobot_model/meshes/collision/segment05_power_collision.stl" scale="0.001 0.001 0.001" />
                </geometry>
            </xacro:if>
            <xacro:unless value="${'$(arg use_collision_meshes)' == 'true'}">
                <origin rpy="0.0 0.0 0.0" xyz="0.0 0.0 0.1"/>
                <geometry>
                    <cylinder radius="0.07" length="0.23"/>
                </geometry>
            </xacro:unless>
        </collision>
        <inertial>
            <mass value="1.1" />
            <origin rpy="0.0 0.0 0.0" xyz="0.0 0.0 0.071" />
            <inertia ixx="0.00623544" iyy="0.00623544" izz="0.00277255" ixy="0.0" ixz="0.0" iyz="0.0" />
        </inertial>
    </link>
    <link name="segment6">
        <visual>
            <origin rpy="0.0 0.0 0.0" xyz="0.0 0.0 0.0" />
            <geometry>
                <mesh filename="package://cobot_model/meshes/visual/segment06_power_visual.stl" scale="0.001 0.001 0.001" />
            </geometry>
            <material name="segment6_material">
                <color rgba="0.835 0.059 0.235 1.0" />
            </material>
        </visual>
        <collision>
            <xacro:if value="${'$(arg use_collision_meshes)' == 'true'}">
                <origin rpy="0.0 0.0 0.0" xyz="0.0 0.0 0.0" />
                <geometry>
                    <mesh filename="package://cobot_model/meshes/collision/segment06_power_collision.stl" scale="0.001 0.001 0.001" />
                </geometry>
             </xacro:if>
            <xacro:unless value="${'$(arg use_collision_meshes)' == 'true'}">
                <origin rpy="0.0 1.57 0.0" xyz="0.12 0.0 -0.04"/>
                <geometry>
                    <cylinder length="0.15" radius="0.04"/>
                </geometry>
            </xacro:unless>
        </collision>
        <inertial>
            <mass value="1.5" />
            <origin rpy="0.0 0.0 0.0" xyz="0.05 0.0 0.0" />
            <inertia ixx="0.00319363" iyy="0.00513113" izz="0.0061625" ixy="0.0" ixz="0.0" iyz="0.0" />
        </inertial>
    </link>
      <link name="segment7">
        <visual>
            <origin rpy="0.0 0.0 0.0" xyz="0.0 0.0 0.0"/>
            <material name="Aterul">
                <color rgba="1.0 1.0 1.0 1.0"/>
            </material>
            <geometry>
                <mesh filename="package://cobot_model/meshes/visual/segment07_real_visual.stl" scale="0.001 0.001 0.001"/>
            </geometry>
        </visual>
        <collision>
            <xacro:if value="${'$(arg use_collision_meshes)' == 'true'}">
                <origin rpy="0.0 0.0 0.0" xyz="0.0 0.0 0.0"/>
                <geometry>
                    <mesh filename="package://cobot_model/meshes/collision/segment07_real_collision.stl" scale="0.001 0.001 0.001"/>
                </geometry>
            </xacro:if>
            <xacro:unless value="${'$(arg use_collision_meshes)' == 'true'}">
                <origin rpy="-0.786 0.0 0.0" xyz="0.0 -0.1 0.05"/>
                <geometry>
                    <box size="0.124 0.135 0.14"/>
                </geometry>
            </xacro:unless>
        </collision>
        <inertial>
            <mass value="4.0"/>
            <origin rpy="0.0 0.0 0.0" xyz="0.0 -0.09 0.04"/>
           <inertia ixx="0.02693367" iyy="0.01533367" izz="0.02185067" ixy="0.0" ixz="0.0" iyz="0.0" />
        </inertial>
  </link>
    <link name="TCP"/>
    <link name="finger1">
        <visual>
           <origin rpy="0.0 0.0 0.0" xyz="0.0 0.065 -0.065"/>
            <material name="silver">
                <color rgba="0.629 0.629 0.625 1.0" />
            </material>
            <geometry>
                <mesh filename="package://cobot_model/meshes/visual/finger01_real_visual.stl" scale="0.001 0.001 0.001" />
            </geometry>
        </visual>
        <collision>
            <xacro:if value="${'$(arg use_collision_meshes)' == 'true'}">
                <origin rpy="0.0 0.0 0.0" xyz="0.0 0.065 -0.065"/>
                <geometry>
                    <mesh filename="package://cobot_model/meshes/collision/finger01_real_collision.stl" scale="0.001 0.001 0.001" />
                </geometry>
            </xacro:if>
            <xacro:unless value="${'$(arg use_collision_meshes)' == 'true'}">
                <origin rpy="-0.786 0.25 0.0" xyz="-0.020 0.040 0.036"/>
                <geometry>
                    <cylinder length="0.10" radius="0.01"/>
                </geometry>
            </xacro:unless>
        </collision>
        <inertial>
            <mass value="0.05" />
            <origin rpy="-0.785 0.0 0.0" xyz="0.02 0.03 0.03" />
            <inertia ixx="3.46666667e-05" iyy="2.64166667e-05" izz="1.78833333e-05" ixy="0.0" ixz="0.0" iyz="0.0" />
        </inertial>
    </link>
    <link name="finger2">
        <visual>
            <origin rpy="0.0 0.0 0.0" xyz="0.0 0.065 -0.065"/>
            <material name="silver">
                <color rgba="0.629 0.629 0.625 1.0" />
            </material>
            <geometry>
                <mesh filename="package://cobot_model/meshes/visual/finger02_real_visual.stl" scale="0.001 0.001 0.001" />
            </geometry>
        </visual>
        <collision>
            <xacro:if value="${'$(arg use_collision_meshes)' == 'true'}">
                <origin rpy="0.0 0.0 0.0" xyz="0.0 0.065 -0.065"/>
                <geometry>
                    <mesh filename="package://cobot_model/meshes/collision/finger02_real_collision.stl" scale="0.001 0.001 0.001" />
                </geometry>
            </xacro:if>
            <xacro:unless value="${'$(arg use_collision_meshes)' == 'true'}">
                <origin rpy="-0.786 -0.25 0.0" xyz="0.020 0.040 0.036"/>
                <geometry>
                    <cylinder length="0.10" radius="0.01"/>
                </geometry>
            </xacro:unless>
        </collision>
        <inertial>
            <mass value="0.05" />
            <origin rpy="-0.785 0.0 0.0" xyz="-0.02 0.03 0.03" />
            <inertia ixx="3.46666667e-05" iyy="2.64166667e-05" izz="1.78833333e-05" ixy="0.0" ixz="0.0" iyz="0.0" />
        </inertial>
    </link>
    <link name="vacuum_gripper_up">
    <visual>
      <origin rpy="0.0 0.0 0.0" xyz="0.0 0.026 -0.103"/>
      <material name="silver">
        <color rgba="0.629 0.629 0.625 1.0"/>
      </material>
      <geometry>
        <mesh filename="package://cobot_model/meshes/visual/vacuum_gripper_up_visual.stl" scale="0.001 0.001 0.001"/>
      </geometry>
    </visual>
    <collision>
    <xacro:if value="${'$(arg use_collision_meshes)' == 'true'}">
        <origin rpy="0.0 0.0 0.0" xyz="0.0 0.026 -0.103"/>
        <geometry>
            <mesh filename="package://cobot_model/meshes/collision/vacuum_gripper_up_collision.stl" scale="0.001 0.001 0.001"/>
        </geometry>
    </xacro:if>
    <xacro:unless value="${'$(arg use_collision_meshes)' == 'true'}">
        <origin rpy="-0.786 0.0 0.0" xyz="0.0 -0.008 0.042"/>
        <geometry>
            <cylinder length="0.10" radius="0.01"/>
        </geometry>
    </xacro:unless>
    </collision>
    <inertial>
      <mass value="0.05"/>
      <origin rpy="-0.785 0.0 0.0" xyz="0.0 0.001 0.052"/>
      <inertia ixx="3.46666667e-05" ixy="0.0" ixz="0.0" iyy="2.64166667e-05" iyz="0.0" izz="1.78833333e-05"/>
    </inertial>
  </link>
  <link name="vacuum_gripper_down">
    <visual>
      <origin rpy="0.0 0.0 0.0" xyz="0.0 0.026 -0.103"/>
      <material name="silver">
        <color rgba="0.629 0.629 0.625 1.0"/>
      </material>
      <geometry>
        <mesh filename="package://cobot_model/meshes/visual/vacuum_gripper_down_visual.stl" scale="0.001 0.001 0.001"/>
      </geometry>
    </visual>
    <collision>
        <xacro:if value="${'$(arg use_collision_meshes)' == 'true'}">
            <origin rpy="0.0 0.0 0.0" xyz="0.0 0.026 -0.103"/>
            <geometry>
                <mesh filename="package://cobot_model/meshes/collision/vacuum_gripper_down_collision.stl" scale="0.001 0.001 0.001"/>
            </geometry>
        </xacro:if>
       <xacro:unless value="${'$(arg use_collision_meshes)' == 'true'}">
            <origin rpy="-0.786 0.0 0.0" xyz="0.0 0.042 -0.008"/>
            <geometry>
                <cylinder length="0.10" radius="0.01"/>
            </geometry>
       </xacro:unless>
    </collision>
    <inertial>
      <mass value="0.05"/>
      <origin rpy="-0.785 0.0 0.0" xyz="0.0 0.052 0.001"/>
      <inertia ixx="3.46666667e-05" ixy="0.0" ixz="0.0" iyy="2.64166667e-05" iyz="0.0" izz="1.78833333e-05"/>
    </inertial>
  </link>
    <!-- Joints -->
    <joint name="joint_0" type="prismatic">
        <origin rpy="0.0 0.0 0.0" xyz="0.0 0.0 0.0" />
        <parent link="lin_axis" />
        <child link="lin_axis_carriage" />
        <axis xyz="0 0 1" />
        <limit effort="300.0" velocity="3.141593" lower="-0.001" upper="0.894" />
    </joint>
    <joint name="mount_fixture" type="fixed">
        <origin rpy="0.0 0.0 0.0" xyz="0.0 0.37 0.52" />
        <parent link="lin_axis_carriage" />
        <child link="segment1" />
    </joint>
    <joint name="joint_1" type="revolute">
        <origin rpy="0.0 0.0 -3.14" xyz="0.0 0.0 0.0" />
        <parent link="segment1" />
        <child link="segment2" />
        <axis xyz="0 0 1" />
        <limit effort="200.0" velocity="3.141593" lower="-2.37365" upper="2.37365" />
        <dynamics damping="0.0" friction="0.0" />
    </joint>
    <joint name="joint_2" type="revolute">
        <origin rpy="1.5708 -1.5708 0.0" xyz="0.0 -0.111 0.118" />
        <parent link="segment2" />
        <child link="segment3" />
        <axis xyz="0 0 1" />
        <limit effort="150.0" velocity="3.141593" lower="-2.26893" upper="0.785398" />
        <dynamics damping="0.0" friction="0.0" />
    </joint>
    <joint name="joint_3" type="revolute">
        <origin rpy="0.0 0.0 -1.57" xyz="0.254 0.0 0.06" />
        <parent link="segment3" />
        <child link="segment4" />
        <axis xyz="0 0 1" />
        <limit effort="100.0" velocity="3.141593" lower="-0.785398" upper="2.26893" />
        <dynamics damping="0.0" friction="0.0" />
    </joint>
    <joint name="joint_4" type="revolute">
        <origin rpy="-1.5708 0.0 -1.5708" xyz="0.062 0.0 -0.168"/>
        <parent link="segment4" />
        <child link="segment5" />
        <axis xyz="0 0 1" />
        <limit effort="50.0" velocity="3.141593" lower="-1.570796" upper="1.570796" />
        <dynamics damping="0.0" friction="0.0" />
    </joint>
    <joint name="joint_5" type="revolute">
        <origin rpy="-1.570 -1.570 0.0" xyz="0.0 0.042 0.183" />
        <parent link="segment5" />
        <child link="segment6" />
        <axis xyz="0 0 1" />
        <limit effort="50.0" velocity="3.141593" lower="-1.570796" upper="1.570796" />
        <dynamics damping="0.0" friction="0.0" />
    </joint>
    <joint name="joint_6" type="revolute">
        <origin rpy="0.0 1.57 0.0" xyz="0.156 0.0 -0.04"/>
        <parent link="segment6"/>
        <child link="segment7"/>
        <axis xyz="0 0 1"/>
        <limit effort="20." lower="-2.37365" upper="2.37365" velocity="3.141593"/>
        <dynamics damping="0.0" friction="0.0"/>
    </joint>
    <joint name="JFix_TCP" type="fixed">
        <origin rpy="-0.785 0.0 0.0" xyz="0.0 -0.02 0.12"/>
        <parent link="segment7"/>
        <child link="TCP"/>
    </joint>
   <joint name="JFix_Base" type="fixed">
        <origin rpy="0.0 0.0 0.0" xyz="0.0 0.0 0.0" />
        <parent link="base_link" />
        <child link="lin_axis" />
    </joint>
    <joint name="finger1_joint" type="prismatic">
        <origin rpy="0.0 0.0 0.0" xyz="-0.02 -0.065 0.065"/>
        <parent link="segment7" />
        <child link="finger1" />
        <axis xyz="1 0 0" />
        <limit effort="30.0" velocity="0.1" lower="-0.01" upper="0.029" />
    </joint>
    <joint name="finger2_joint" type="prismatic">
        <origin rpy="0.0 0.0 0.0" xyz="0.02 -0.065 0.065"/>
        <parent link="segment7" />
        <child link="finger2" />
        <axis xyz="-1 0 0" />
        <limit effort="30.0" velocity="0.1" lower="-0.01" upper="0.029" />
        <mimic joint="finger1_joint" />
    </joint>
    <joint name="vacuum_up_joint" type="prismatic">
        <origin rpy="0.0 0.0 0.0" xyz="0.0 -0.065 0.065"/>
        <parent link="segment7"/>
        <child link="vacuum_gripper_up"/>
        <!-- The head of the cobot is rotated by 45deg => joint moves in two directions -->
        <!-- TODO @rharbach normalize: <axis xyz="0 0.70710678 0.70710678"/> -->
        <axis xyz="0 1 1"/>
        <limit effort="30.0" lower="-0.01" upper="0.036" velocity="0.1"/>
    </joint>
    <joint name="vacuum_down_joint" type="prismatic">
        <origin rpy="0.0 0.0 0.0" xyz="0.0 -0.065 0.065"/>
        <parent link="segment7"/>
        <child link="vacuum_gripper_down"/>
        <axis xyz="0 1 1"/>
        <limit effort="30.0" lower="-0.01" upper="0.036" velocity="0.1"/>
    </joint>
</robot>