<?xml version="1.0" ?>
<robot xmlns:xacro="http://www.ros.org/wiki/xacro">
    <link name="world" />
    <joint name="robot_in_world" type="fixed">
        <origin xyz="0.0 0.0 0.3" rpy="0.0 0.0 0.0" />
        <parent link="world" />
        <child link="base_link" />
        <axis xyz="0 0 1" />
    </joint>
    <!-- Links -->
    <link name="base_link" />
    <link name="lin_axis">
        <visual>
            <origin rpy="-1.570796327 3.141592654 0.0" xyz="0.0 -0.5 -0.32" />
            <geometry>
                <mesh filename="package://cobot_model/meshes/lin_axis/axis.dae" scale="0.001 0.001 0.001" />
                <material name="silver">
                    <color rgba="1.0 1.0 1.0 1.0" />
                </material>
            </geometry>
        </visual>
        <collision>
            <origin rpy="-1.570796327 3.141592654 0.0" xyz="0.0 -0.5 -0.32" />
            <geometry>
                <mesh filename="package://cobot_model/meshes/lin_axis/axis.dae" scale="0.001 0.001 0.001" />
            </geometry>
        </collision>
        <inertial>
            <mass value="100.1" />
            <origin rpy="-1.570796327 3.141592654 0.0" xyz="0.0 -0.5 -0.32" />
            <inertia ixx="0.3" iyy="0.3" izz="0.3" ixy="0.0" ixz="0.0" iyz="0.0" />
        </inertial>
    </link>
    <link name="lin_axis_carriage">
        <visual>
            <origin rpy="-1.570796327 3.141592654 0.0" xyz="0.0 0.0 -0.32" />
            <geometry>
                <mesh filename="package://cobot_model/meshes/lin_axis/carriage.dae" scale="0.001 0.001 0.001" />
                <material name="silver">
                    <color rgba="1.0 1.0 1.0 1.0" />
                </material>
            </geometry>
        </visual>
        <collision>
            <origin rpy="-1.570796327 3.141592654 0.0" xyz="0.0 0.0 -0.32" />
            <geometry>
                <mesh filename="package://cobot_model/meshes/lin_axis/carriage.dae" scale="0.001 0.001 0.001" />
            </geometry>
        </collision>
        <inertial>
            <mass value="1.0" />
            <origin rpy="-1.570796327 3.141592654 0.0" xyz="0.0 0.0 -0.32" />
            <inertia ixx="0.003" iyy="0.003" izz="0.003" ixy="0.0" ixz="0.0" iyz="0.0" />
        </inertial>
    </link>
    <link name="segment1">
        <visual>
            <origin rpy="-1.570793 -0.0 3.141593" xyz="0.0 -0.311 0.0" />
            <geometry>
                <mesh filename="package://cobot_model/meshes/v2_0_hull/segment01_combined.stl" scale="0.001 0.001 0.001" />
            </geometry>
            <material name="segment1_material">
                <color rgba="0.0 0.0 0.0 1.0" />
            </material>
        </visual>
        <collision>
            <origin rpy="-1.570793 0.0 3.141593" xyz="0.0 -0.311 0.0" />
            <geometry>
                <mesh filename="package://cobot_model/meshes/v2_0_hull/segment01_combined.stl" scale="0.001 0.001 0.001" />
            </geometry>
        </collision>
        <inertial>
            <mass value="2.0" />
            <origin rpy="-1.570793 0.0 3.141593" xyz="0.0 -0.311 0.0" />
            <inertia ixx="0.0075496764161139766" iyy="0.009" izz="0.007" ixy="0.0" ixz="0.0" iyz="0.0" />
        </inertial>
    </link>
    <link name="segment2">
        <visual>
            <origin rpy="0.0 0.0 3.1415" xyz="0.0 0.0 0.036" />
            <geometry>
                <mesh filename="package://cobot_model/meshes/v2_0_hull/segment02_combined.stl" scale="0.001 0.001 0.001" />
            </geometry>
            <material name="segment2_material">
                <color rgba="1.0 1.0 1.0 1.0" />
            </material>
        </visual>
        <collision>
            <origin rpy="0.0 0.0 3.1415" xyz="0.0 0.0 0.036" />
            <geometry>
                <mesh filename="package://cobot_model/meshes/v2_0_hull/segment02_combined.stl" scale="0.001 0.001 0.001" />
            </geometry>
        </collision>
        <inertial>
            <mass value="1.0" />
            <origin rpy="0.0 0.0 3.1415" xyz="0.0 0.0 0.036" />
            <inertia ixx="0.03" iyy="0.03" izz="0.03" ixy="0.0" ixz="0.0" iyz="0.0" />
        </inertial>
    </link>
    <link name="segment3">
        <visual>
            <origin rpy="0.0 0.0 3.1415" xyz="0.001 0.0 0.06" />
            <geometry>
                <mesh filename="package://cobot_model/meshes/v2_0_hull/segment03_combined.stl" scale="0.001 0.001 0.001" />
            </geometry>
            <material name="segment3_material">
                <color rgba="0.0 0.0 0.0 1.0" />
            </material>
        </visual>
        <collision>
            <origin rpy="0.0 0.0 3.1415" xyz="0.001 0.0 0.06" />
            <geometry>
                <mesh filename="package://cobot_model/meshes/v2_0_hull/segment03_combined.stl" scale="0.001 0.001 0.001" />
            </geometry>
        </collision>
        <inertial>
            <mass value="0.1" />
            <origin rpy="0.0 0.0 3.1415" xyz="0.001 0.0 0.06" />
            <inertia ixx="0.03" iyy="0.03" izz="0.03" ixy="0.0" ixz="0.0" iyz="0.0" />
        </inertial>
    </link>
    <link name="segment4">
        <visual>
            <origin rpy="3.1415 0.0 -1.5707 " xyz="0.0 0.0 -0.035" />
            <geometry>
                <mesh filename="package://cobot_model/meshes/v2_0_hull/segment04_combined.stl" scale="0.001 0.001 0.001" />
            </geometry>
            <material name="segment4_material">
                <color rgba="1.0 1.0 1.0 1.0" />
            </material>
        </visual>
        <collision>
            <origin rpy="3.1415 0.0 -1.5707 " xyz="0.0 0.0 -0.035" />
            <geometry>
                <mesh filename="package://cobot_model/meshes/v2_0_hull/segment04_combined.stl" scale="0.001 0.001 0.001" />
            </geometry>
        </collision>
        <inertial>
            <mass value="1.0" />
            <origin rpy="3.1415 0.0 -1.5707 " xyz="0.0 0.0 -0.035" />
            <inertia ixx="0.003" iyy="0.003" izz="0.003" ixy="0.0" ixz="0.0" iyz="0.0" />
        </inertial>
    </link>
    <link name="segment5">
        <visual>
            <origin rpy="0.0 0.0 3.1415" xyz="0.0 0.0 0.015" />
            <geometry>
                <mesh filename="package://cobot_model/meshes/v2_0_hull/segment05_combined.stl" scale="0.001 0.001 0.001" />
            </geometry>
            <material name="segment5_material">
                <color rgba="0.0 0.0 0.0 1.0" />
            </material>
        </visual>
        <collision>
            <origin rpy="0.0 0.0 3.1415" xyz="0.0 0.0 0.015" />
            <geometry>
                <mesh filename="package://cobot_model/meshes/v2_0_hull/segment05_combined.stl" scale="0.001 0.001 0.001" />
            </geometry>
        </collision>
        <inertial>
            <mass value="0.5" />
            <origin rpy="0.0 0.0 3.1415" xyz="0.0 0.0 0.015" />
            <inertia ixx="0.001" iyy="0.001" izz="0.001" ixy="0.0" ixz="0.0" iyz="0.0" />
        </inertial>
    </link>
    <link name="segment6">
        <visual>
            <origin rpy="0.0 0.0 -1.5708" xyz="0.005 0.0 0.038" />
            <geometry>
                <mesh filename="package://cobot_model/meshes/v2_0_hull/segment06_combined.stl" scale="0.001 0.001 0.001" />
            </geometry>
            <material name="segment6_material">
                <color rgba="1.0 1.0 1.0 1.0" />
            </material>
        </visual>
        <collision>
            <origin rpy="0.0 0.0 -1.5708" xyz="0.005 0.0 0.038" />
            <geometry>
                <mesh filename="package://cobot_model/meshes/v2_0_hull/segment06_combined.stl" scale="0.001 0.001 0.001" />
            </geometry>
        </collision>
        <inertial>
            <mass value="0.1" />
            <origin rpy="0.0 0.0 -1.5708" xyz="0.005 0.0 0.038" />
            <inertia ixx="0.03" iyy="0.03" izz="0.03" ixy="0.0" ixz="0.0" iyz="0.0" />
        </inertial>
    </link>
    <link name="segment7">
        <visual>
            <origin rpy="0.0 0.0 0.0" xyz="0.004 0.002 0.091" />
            <material name="Aterul">
                <color rgba="0.0 0.0 0.0 1.0" />
            </material>
            <geometry>
                <mesh filename="package://cobot_model/meshes/v2_0_hull/segment07_black.stl" scale="0.001 0.001 0.001" />
            </geometry>
        </visual>
        <collision>
            <origin rpy="0.0 0.0 0.0" xyz="0.004 0.002 0.091" />
            <geometry>
                <mesh filename="package://cobot_model/meshes/v2_0_hull/segment07_black.stl" scale="0.001 0.001 0.001" />
            </geometry>
        </collision>
        <inertial>
            <mass value="0.1" />
            <origin rpy="0.0 0.0 0.0" xyz="0.004 0.002 0.091" />
            <inertia ixx="0.03" iyy="0.03" izz="0.03" ixy="0.0" ixz="0.0" iyz="0.0" />
        </inertial>
    </link>
    <link name="finger1">
        <visual>
            <origin rpy="0.0 -0.000000 0.000000" xyz="0.0 0.0 0.0" />
            <material name="silver">
                <color rgba="0.629 0.629 0.625 1.0" />
            </material>
            <geometry>
                <mesh filename="package://cobot_model/meshes/v2_0_hull/finger01.stl" scale="0.000001 0.000001 0.000001" />
            </geometry>
        </visual>
        <collision>
            <origin rpy="0.0 -0.000000 0.000000" xyz="0.0 0.0 0.0" />
            <geometry>
                <mesh filename="package://cobot_model/meshes/v2_0_hull/finger01.stl" scale="0.000001 0.000001 0.000001" />
            </geometry>
        </collision>
        <inertial>
            <mass value="0.001" />
            <inertia ixx="100.0" iyy="100.0" izz="100.0" ixy="0.0" ixz="0.0" iyz="0.0" />
            <origin xyz="0.0 0.0 0.0" rpy="0.0 0.0 0.0" />
        </inertial>
    </link>
    <link name="finger2">
        <visual>
            <origin rpy="0.0 -0.000000 0.000000" xyz="0.0 0.0 0.0" />
            <material name="silver">
                <color rgba="0.629 0.629 0.625 1.0" />
            </material>
            <geometry>
                <mesh filename="package://cobot_model/meshes/v2_0_hull/finger02.stl" scale="0.000001 0.000001 0.000001" />
            </geometry>
        </visual>
        <collision>
            <origin rpy="0.0 -0.000000 0.000000" xyz="0.0 0.0 0.0" />
            <geometry>
                <mesh filename="package://cobot_model/meshes/v2_0_hull/finger02.stl" scale="0.000001 0.000001 0.000001" />
            </geometry>
        </collision>
        <inertial>
            <mass value="0.001" />
            <inertia ixx="100.0" iyy="100.0" izz="100.0" ixy="0.0" ixz="0.0" iyz="0.0" />
            <origin xyz="0.0 0.0 0.0" rpy="0.0 0.0 0.0" />
        </inertial>
    </link>
    <link name="TCP">
        <visual>
            <origin xyz="-0.005 -0.002 0.01" rpy="0.0 0.0 0.0" />
            <geometry>
                <cylinder radius="0.00001" length="0.000001" />
            </geometry>
            <material name="silver">
                <color rgba="0.629 0.629 0.625 1.0" />
            </material>
        </visual>
       <!-- <collision>
            <origin xyz="-0.005 -0.002 0.010" rpy = "0 0 0" />
            <geometry>
                <cylinder radius="0.00001" length="0.000001" />
            </geometry>
        </collision> -->
    </link>
    <!-- Joints -->
    <joint name="joint_0" type="prismatic">
        <origin rpy="0.0 0.0 0.0" xyz="0.0 0.0 0.0" />
        <parent link="lin_axis" />
        <child link="lin_axis_carriage" />
        <axis xyz="0 1 0" />
        <limit effort="200.000" velocity="3.141593" lower="-.35" upper=".55" />
    </joint>
    <joint name="mount_fixture" type="fixed">
        <origin rpy="0.0 0.0 0.0" xyz="0.0 0.0 0.0" />
        <parent link="lin_axis_carriage" />
        <child link="segment1" />
    </joint>
    <joint name="joint_1" type="revolute">
        <origin rpy="-1.570793 0.0 3.141593" xyz="0.0 -0.274400 0.0" />
        <parent link="segment1" />
        <child link="segment2" />
        <axis xyz="0 0 1" />
        <limit effort="40.0" velocity="3.141593" lower="-0.7853976732051033" upper="3.9269903267948965" />
        <dynamics damping="0.0" friction="0.0" />
    </joint>
    <joint name="joint_2" type="revolute">
        <origin rpy="-1.570796 0.0 0.0" xyz="0.00005 0.04955 0.1555" />
        <parent link="segment2" />
        <child link="segment3" />
        <axis xyz="0 0 1" />
        <limit effort="20.0" velocity="3.141593" lower="-1.570796" upper="1.570796" />
        <dynamics damping="0.0" friction="0.0" />
    </joint>
    <joint name="joint_3" type="revolute">
        <origin rpy="3.141593 0.0 1.570796" xyz="-0.254493 0.0 0.0852" />
        <parent link="segment3" />
        <child link="segment4" />
        <axis xyz="0 0 1" />
        <limit effort="10.0" velocity="3.141593" lower="-1.570796" upper="1.570796" />
        <dynamics damping="0.0" friction="0.0" />
    </joint>
    <joint name="joint_4" type="revolute">
        <origin rpy="-1.570796 0.0 -3.141593" xyz="0.0 -0.0076 0.132393" />
        <parent link="segment4" />
        <child link="segment5" />
        <axis xyz="0 0 1" />
        <limit effort="10.0" velocity="3.141593" lower="-1.570796" upper="1.570796" />
        <dynamics damping="0.0" friction="0.0" />
    </joint>
    <joint name="joint_5" type="revolute">
        <origin rpy="-1.570796 0.0 3.141593" xyz="0.0 -0.0063 0.113264" />
        <parent link="segment5" />
        <child link="segment6" />
        <axis xyz="0 0 1" />
        <limit effort="10.0" velocity="3.141593" lower="-1.570796" upper="1.570796" />
        <dynamics damping="0.0" friction="0.0" />
    </joint>
    <joint name="joint_6" type="revolute">
        <origin rpy="1.570796 0.0 0.0" xyz="0.0 -0.1328 -0.006164" />
        <parent link="segment6" />
        <child link="segment7" />
        <axis xyz="0 0 1" />
        <limit effort="10." velocity="3.141593" lower="-2.356194" upper="2.356194" />
        <dynamics damping="0.0" friction="0.0" />
    </joint>
    <joint name="JFix_TCP" type="fixed">
        <origin rpy="0.0 0.0 3.141593" xyz="0.0 0.0 0.190143" />
        <parent link="segment7" />
        <child link="TCP" />
    </joint>
    <joint name="JFix_Base" type="fixed">
        <origin rpy="-1.570796 0.0 0.0" xyz="0.0 0.0 0.5" />
        <parent link="base_link" />
        <child link="lin_axis" />
    </joint>
    <joint name="finger1_joint" type="prismatic">
        <origin rpy="0.0 0.0 0.0" xyz="0.000000 0.0000 0.000000" />
        <parent link="TCP" />
        <child link="finger1" />
        <axis xyz="0 1 0" />
        <limit effort="30.0" velocity="0.1" lower="-0.01" upper="0.015" />
    </joint>
    <joint name="finger2_joint" type="prismatic">
        <origin rpy="0.0 0.0 0.0" xyz="0.000000 0.0000 0.000000" />
        <parent link="TCP" />
        <child link="finger2" />
        <axis xyz="0 1 0" />
        <limit effort="30.0" velocity="0.1" lower="-0.01" upper="0.015" />
    </joint>    
</robot>